tests/test2.txt
A,1,B,782,962.0
A,2,S,699,1194.0
A,3,B,763,934.0
A,4,S,950,1116.0
A,5,B,560,909.0
A,6,S,781,1151.0
A,7,B,790,920.0
A,8,S,660,1059.0
A,9,B,154,902.0
A,10,S,500,1181.0
A,11,B,365,900.0
A,12,S,671,1078.0
A,13,B,122,975.0
A,14,S,560,1059.0
A,15,B,799,1003.0
A,16,S,733,1102.0
A,17,B,949,1041.0
A,18,S,583,1178.0
A,19,B,815,964.0
A,20,S,678,1151.0
T,660,1059
T,63,1059
X,8,S,660,1059.0
M,14,S,497,1059.0
T,497,1059
T,18,1078
X,14,S,497,1059.0
M,12,S,653,1078.0
T,586,1041
M,17,B,363,1041.0
T,343,1078
M,12,S,310,1078.0
T,363,1041
T,365,1003
X,17,B,363,1041.0
M,15,B,434,1003.0
T,310,1078
T,452,1102
X,12,S,310,1078.0
M,16,S,281,1102.0
T,281,1102
X,16,S,281,1102.0
A,27,B,98,1108.0
A,28,B,738,1098.0
T,98,1108
T,331,1098
X,27,B,98,1108.0
M,28,B,407,1098.0
A,30,B,383,1099.0
T,538,1116
M,4,S,412,1116.0
T,112,1116
M,4,S,300,1116.0
T,383,1099
T,339,1098
X,30,B,383,1099.0
M,28,B,68,1098.0
T,68,1098
T,434,1003
X,28,B,68,1098.0
X,15,B,434,1003.0
A,34,S,431,1003.0
T,11,1003
M,34,S,420,1003.0
T,148,1003
M,34,S,272,1003.0
T,122,975
T,815,964
T,49,962
X,13,B,122,975.0
X,19,B,815,964.0
M,1,B,733,962.0
T,252,962
M,1,B,481,962.0
T,481,962
T,357,934
X,1,B,481,962.0
M,3,B,406,934.0
T,272,1003
X,34,S,272,1003.0
A,40,B,723,1111.0
T,723,1111
X,40,B,723,1111.0
A,41,S,174,1022.0
T,174,1022
T,300,1116
X,41,S,174,1022.0
X,4,S,300,1116.0
A,42,B,455,1133.0
A,43,B,746,1135.0
A,44,B,196,1083.0
T,269,1135
M,43,B,477,1135.0
T,477,1135
T,44,1133
X,43,B,477,1135.0
M,42,B,411,1133.0
T,201,1151
M,6,S,580,1151.0
T,580,1151
T,292,1151
X,6,S,580,1151.0
M,20,S,386,1151.0
T,411,1133
T,196,1083
X,42,B,411,1133.0
X,44,B,196,1083.0
A,49,S,149,965.0
A,50,S,908,1030.0
A,51,S,583,1026.0
T,149,965
T,508,1026
X,49,S,149,965.0
M,51,S,75,1026.0
A,53,S,227,1020.0
A,54,S,239,935.0
T,108,934
M,3,B,298,934.0
T,107,934
M,3,B,191,934.0
A,57,S,45,964.0
A,58,S,548,973.0
T,239,935
T,45,964
T,20,973
X,54,S,239,935.0
X,57,S,45,964.0
M,58,S,528,973.0
A,60,S,880,939.0
T,191,934
T,705,920
X,3,B,191,934.0
M,7,B,85,920.0
A,62,S,112,989.0
A,63,S,560,1004.0
A,64,S,983,960.0
A,65,S,386,934.0
T,386,934
T,228,939
X,65,S,386,934.0
M,60,S,652,939.0
A,67,S,556,958.0
T,137,939
M,60,S,515,939.0
T,136,939
M,60,S,379,939.0
A,70,S,889,924.0
A,71,S,514,973.0
T,548,924
M,70,S,341,924.0
A,73,S,254,923.0
T,254,923
T,341,924
T,230,939
X,73,S,254,923.0
X,70,S,341,924.0
M,60,S,149,939.0
T,149,939
T,556,958
T,245,960
X,60,S,149,939.0
X,67,S,556,958.0
M,64,S,738,960.0
A,76,S,774,962.0
T,738,960
T,188,962
X,64,S,738,960.0
M,76,S,586,962.0
T,271,962
M,76,S,315,962.0
T,315,962
T,169,973
X,76,S,315,962.0
M,58,S,359,973.0
A,80,S,830,981.0
T,359,973
T,396,973
X,58,S,359,973.0
M,71,S,118,973.0
A,82,S,81,969.0
T,81,969
T,118,973
T,335,981
X,82,S,81,969.0
X,71,S,118,973.0
M,80,S,495,981.0
T,63,981
M,80,S,432,981.0
A,85,S,316,1010.0
T,432,981
T,112,989
T,166,1004
X,80,S,432,981.0
X,62,S,112,989.0
M,63,S,394,1004.0
T,394,1004
T,57,1010
X,63,S,394,1004.0
M,85,S,259,1010.0
A,88,S,537,1021.0
T,259,1010
T,227,1020
T,200,1021
X,85,S,259,1010.0
X,53,S,227,1020.0
M,88,S,337,1021.0
T,337,1021
T,75,1026
T,289,1030
X,88,S,337,1021.0
X,51,S,75,1026.0
M,50,S,619,1030.0
T,466,1030
M,50,S,153,1030.0
T,153,1030
X,50,S,153,1030.0
A,92,B,461,1092.0
T,461,1092
X,92,B,461,1092.0
A,93,S,494,940.0
A,94,S,794,960.0
T,85,920
X,7,B,85,920.0
A,95,S,454,911.0
A,96,S,823,948.0
T,183,911
M,95,S,271,911.0
T,84,909
M,5,B,476,909.0
T,271,911
T,494,940
T,209,948
X,95,S,271,911.0
X,93,S,494,940.0
M,96,S,614,948.0
T,170,948
M,96,S,444,948.0
A,101,S,340,1013.0
T,310,948
M,96,S,134,948.0
T,134,948
T,202,960
X,96,S,134,948.0
M,94,S,592,960.0
A,104,S,337,1035.0
A,105,S,429,998.0
A,106,S,699,924.0
T,699,924
T,27,960
X,106,S,699,924.0
M,94,S,565,960.0
A,108,S,446,972.0
T,197,960
M,94,S,368,960.0
A,110,S,679,992.0
