tests/test4.txt
A,1,B,999,996.0
A,2,S,183,1176.0
A,3,B,932,1003.0
A,4,S,961,1098.0
A,5,B,654,970.0
A,6,S,378,1086.0
A,7,B,343,977.0
A,8,S,802,1145.0
A,9,B,182,912.0
A,10,S,893,1174.0
A,11,B,722,981.0
A,12,S,479,1164.0
A,13,B,758,924.0
A,14,S,318,1154.0
A,15,B,185,922.0
A,16,S,165,1101.0
A,17,B,375,958.0
A,18,S,476,1150.0
A,19,B,792,1000.0
A,20,S,164,1139.0
T,257,1003
M,3,B,675,1003.0
A,22,B,623,1071.0
T,378,1086
T,475,1098
X,6,S,378,1086.0
M,4,S,486,1098.0
T,156,1071
M,22,B,467,1071.0
A,25,B,911,1070.0
T,486,1098
T,165,1101
T,164,1139
T,26,1145
X,4,S,486,1098.0
X,16,S,165,1101.0
X,20,S,164,1139.0
M,8,S,776,1145.0
T,467,1071
T,166,1070
X,22,B,467,1071.0
M,25,B,745,1070.0
T,776,1145
T,216,1150
X,8,S,776,1145.0
M,18,S,260,1150.0
T,81,1150
M,18,S,179,1150.0
A,30,B,839,1082.0
T,822,1082
M,30,B,17,1082.0
T,179,1150
T,313,1154
X,18,S,179,1150.0
M,14,S,5,1154.0
A,33,B,636,1130.0
T,636,1130
T,17,1082
T,127,1070
X,33,B,636,1130.0
X,30,B,17,1082.0
M,25,B,618,1070.0
T,618,1070
T,271,1003
X,25,B,618,1070.0
M,3,B,404,1003.0
A,36,B,397,1127.0
T,397,1127
T,404,1003
T,26,1000
X,36,B,397,1127.0
X,3,B,404,1003.0
M,19,B,766,1000.0
T,278,1000
M,19,B,488,1000.0
A,39,S,620,1004.0
T,614,1004
M,39,S,6,1004.0
T,6,1004
X,39,S,6,1004.0
A,41,B,181,1121.0
A,42,B,529,1123.0
A,43,B,355,1137.0
T,355,1137
T,5,1123
X,43,B,355,1137.0
M,42,B,524,1123.0
T,335,1123
M,42,B,189,1123.0
T,34,1123
M,42,B,155,1123.0
A,47,B,131,1060.0
A,48,B,220,1112.0
T,155,1123
T,181,1121
T,220,1112
T,131,1060
T,261,1000
X,42,B,155,1123.0
X,41,B,181,1121.0
X,48,B,220,1112.0
X,47,B,131,1060.0
M,19,B,227,1000.0
T,5,1154
T,69,1164
X,14,S,5,1154.0
M,12,S,410,1164.0
T,227,1000
T,185,996
X,19,B,227,1000.0
M,1,B,814,996.0
A,52,B,74,1056.0
T,74,1056
X,52,B,74,1056.0
A,53,S,217,1026.0
T,72,996
M,1,B,742,996.0
A,55,S,826,1047.0
T,217,1026
T,636,1047
X,53,S,217,1026.0
M,55,S,190,1047.0
T,673,996
M,1,B,69,996.0
T,69,996
T,633,981
X,1,B,69,996.0
M,11,B,89,981.0
A,59,S,450,1021.0
T,89,981
T,343,977
T,400,970
X,11,B,89,981.0
X,7,B,343,977.0
M,5,B,254,970.0
T,450,1021
T,100,1047
X,59,S,450,1021.0
M,55,S,90,1047.0
T,90,1047
X,55,S,90,1047.0
A,62,B,775,1141.0
T,582,1141
M,62,B,193,1141.0
A,64,B,910,1124.0
T,193,1141
T,721,1124
X,62,B,193,1141.0
M,64,B,189,1124.0
A,66,B,615,1081.0
A,67,B,381,1144.0
T,381,1144
T,57,1124
X,67,B,381,1144.0
M,64,B,132,1124.0
T,132,1124
T,11,1081
X,64,B,132,1124.0
M,66,B,604,1081.0
A,70,B,619,1161.0
A,71,B,850,1073.0
T,410,1164
T,375,1174
X,12,S,410,1164.0
M,10,S,518,1174.0
T,79,1161
M,70,B,540,1161.0
T,540,1161
T,297,1081
X,70,B,540,1161.0
M,66,B,307,1081.0
A,75,B,218,1136.0
A,76,B,780,1098.0
A,77,B,528,1060.0
A,78,B,303,1151.0
T,518,1174
T,183,1176
X,10,S,518,1174.0
X,2,S,183,1176.0
A,79,B,129,1181.0
A,80,B,195,1117.0
T,129,1181
T,303,1151
T,218,1136
T,136,1117
X,79,B,129,1181.0
X,78,B,303,1151.0
X,75,B,218,1136.0
M,80,B,59,1117.0
T,59,1117
T,485,1098
X,80,B,59,1117.0
M,76,B,295,1098.0
T,295,1098
T,298,1081
X,76,B,295,1098.0
M,66,B,9,1081.0
T,9,1081
T,251,1073
X,66,B,9,1081.0
M,71,B,599,1073.0
T,126,1073
M,71,B,473,1073.0
T,473,1073
T,157,1060
X,71,B,473,1073.0
M,77,B,371,1060.0
T,371,1060
T,254,970
T,203,958
X,77,B,371,1060.0
X,5,B,254,970.0
M,17,B,172,958.0
A,88,B,14,1059.0
T,14,1059
X,88,B,14,1059.0
A,89,S,472,980.0
T,172,958
X,17,B,172,958.0
A,90,S,610,940.0
A,91,S,958,938.0
A,92,S,334,1043.0
T,958,938
T,17,940
X,91,S,958,938.0
M,90,S,593,940.0
T,153,940
M,90,S,440,940.0
A,95,S,17,971.0
T,440,940
T,17,971
T,420,980
X,90,S,440,940.0
X,95,S,17,971.0
M,89,S,52,980.0
T,52,980
T,334,1043
X,89,S,52,980.0
X,92,S,334,1043.0
A,97,B,430,1074.0
A,98,B,715,1134.0
T,509,1134
M,98,B,206,1134.0
A,100,B,485,1189.0
T,485,1189
T,62,1134
X,100,B,485,1189.0
M,98,B,144,1134.0
A,102,B,89,1114.0
T,144,1134
T,89,1114
T,430,1074
X,98,B,144,1134.0
X,102,B,89,1114.0
X,97,B,430,1074.0
A,103,S,174,994.0
A,104,S,204,962.0
A,105,S,224,1000.0
A,106,S,941,1018.0
A,107,S,806,968.0
A,108,S,840,1038.0
T,204,962
T,44,968
X,104,S,204,962.0
M,107,S,762,968.0
T,263,968
M,107,S,499,968.0
T,499,968
T,124,994
X,107,S,499,968.0
M,103,S,50,994.0
T,50,994
T,224,1000
T,576,1018
X,103,S,50,994.0
X,105,S,224,1000.0
M,106,S,365,1018.0
T,365,1018
T,179,1038
X,106,S,365,1018.0
M,108,S,661,1038.0
T,661,1038
X,108,S,661,1038.0
A,114,B,64,1085.0
A,115,B,311,1119.0
T,288,1119
M,115,B,23,1119.0
A,117,B,115,1189.0
A,118,B,954,1176.0
T,115,1189
T,330,1176
X,117,B,115,1189.0
M,118,B,624,1176.0
T,601,1176
M,118,B,23,1176.0
A,121,B,458,1186.0
T,458,1186
T,23,1176
T,23,1119
T,31,1085
X,121,B,458,1186.0
X,118,B,23,1176.0
X,115,B,23,1119.0
M,114,B,33,1085.0
T,33,1085
X,114,B,33,1085.0
A,123,S,336,1018.0
T,336,1018
X,123,S,336,1018.0
A,124,B,638,1171.0
A,125,B,463,1157.0
A,126,B,848,1151.0
A,127,B,774,1154.0
A,128,B,341,1090.0
A,129,B,547,1149.0
T,56,1171
M,124,B,582,1171.0
T,332,1171
M,124,B,250,1171.0
A,132,B,251,1106.0
A,133,B,737,1189.0
A,134,B,166,1141.0
T,529,1189
M,133,B,208,1189.0
A,136,B,571,1185.0
A,137,B,17,1090.0
T,137,1189
M,133,B,71,1189.0
T,71,1189
T,40,1185
X,133,B,71,1189.0
M,136,B,531,1185.0
A,140,B,548,1155.0
T,191,1185
M,136,B,340,1185.0
T,300,1185
M,136,B,40,1185.0
T,40,1185
T,250,1171
T,141,1157
X,136,B,40,1185.0
X,124,B,250,1171.0
M,125,B,322,1157.0
T,198,1157
M,125,B,124,1157.0
T,124,1157
T,548,1155
T,80,1154
X,125,B,124,1157.0
X,140,B,548,1155.0
M,127,B,694,1154.0
A,146,B,422,1083.0
T,694,1154
T,87,1151
X,127,B,694,1154.0
M,126,B,761,1151.0
T,761,1151
T,78,1149
X,126,B,761,1151.0
M,129,B,469,1149.0
T,32,1149
M,129,B,437,1149.0
T,437,1149
T,166,1141
T,84,1106
X,129,B,437,1149.0
X,134,B,166,1141.0
M,132,B,167,1106.0
T,167,1106
T,341,1090
T,17,1090
T,222,1083
X,132,B,167,1106.0
X,128,B,341,1090.0
X,137,B,17,1090.0
M,146,B,200,1083.0
T,200,1083
T,637,924
X,146,B,200,1083.0
M,13,B,121,924.0
A,153,B,79,1151.0
T,79,1151
X,153,B,79,1151.0
A,154,S,551,940.0
T,546,940
M,154,S,5,940.0
T,5,940
X,154,S,5,940.0
A,156,B,176,1177.0
T,176,1177
X,156,B,176,1177.0
A,157,S,681,1010.0
A,158,S,627,959.0
T,60,959
M,158,S,567,959.0
A,160,S,168,1049.0
A,161,S,913,1019.0
T,567,959
T,183,1010
X,158,S,567,959.0
M,157,S,498,1010.0
A,163,S,290,999.0
T,290,999
T,255,1010
X,163,S,290,999.0
M,157,S,243,1010.0
A,165,S,997,1026.0
T,243,1010
T,540,1019
X,157,S,243,1010.0
M,161,S,373,1019.0
T,373,1019
T,518,1026
X,161,S,373,1019.0
M,165,S,479,1026.0
T,456,1026
M,165,S,23,1026.0
T,23,1026
T,168,1049
X,165,S,23,1026.0
X,160,S,168,1049.0
A,169,B,574,1074.0
T,181,1074
M,169,B,393,1074.0
T,107,1074
M,169,B,286,1074.0
A,172,B,346,1096.0
T,346,1096
T,6,1074
X,172,B,346,1096.0
M,169,B,280,1074.0
T,151,1074
M,169,B,129,1074.0
A,175,B,420,1058.0
A,176,B,789,1089.0
A,177,B,747,1172.0
A,178,B,875,1090.0
T,181,1172
M,177,B,566,1172.0
T,18,1172
M,177,B,548,1172.0
A,181,B,94,1057.0
A,182,B,317,1120.0
T,548,1172
T,189,1120
X,177,B,548,1172.0
M,182,B,128,1120.0
A,184,B,326,1148.0
T,326,1148
T,128,1120
T,42,1090
X,184,B,326,1148.0
X,182,B,128,1120.0
M,178,B,833,1090.0
A,186,B,506,1125.0
A,187,B,336,1106.0
T,12,1125
M,186,B,494,1125.0
T,334,1125
M,186,B,160,1125.0
T,160,1125
T,143,1106
X,186,B,160,1125.0
M,187,B,193,1106.0
A,191,B,238,1059.0
A,192,B,437,1192.0
A,193,B,460,1059.0
T,324,1192
M,192,B,113,1192.0
T,113,1192
T,193,1106
T,240,1090
X,192,B,113,1192.0
X,187,B,193,1106.0
M,178,B,593,1090.0
A,196,B,333,1169.0
A,197,B,176,1074.0
A,198,B,696,1076.0
T,333,1169
T,146,1090
X,196,B,333,1169.0
M,178,B,447,1090.0
T,400,1090
M,178,B,47,1090.0
A,201,B,822,1097.0
T,822,1097
T,47,1090
T,50,1089
X,201,B,822,1097.0
X,178,B,47,1090.0
M,176,B,739,1089.0
A,203,B,667,1197.0
A,204,B,436,1171.0
A,205,B,881,1182.0
T,31,1197
M,203,B,636,1197.0
A,207,B,258,1124.0
A,208,B,962,1174.0
A,209,B,911,1060.0
T,378,1197
M,203,B,258,1197.0
T,258,1197
T,94,1182
X,203,B,258,1197.0
M,205,B,787,1182.0
A,212,B,922,1199.0
T,638,1199
M,212,B,284,1199.0
T,284,1199
T,335,1182
X,212,B,284,1199.0
M,205,B,452,1182.0
T,413,1182
M,205,B,39,1182.0
T,39,1182
T,64,1174
X,205,B,39,1182.0
M,208,B,898,1174.0
T,894,1174
M,208,B,4,1174.0
A,218,B,353,1081.0
A,219,B,822,1112.0
A,220,B,148,1134.0
T,4,1174
T,290,1171
X,208,B,4,1174.0
M,204,B,146,1171.0
T,146,1171
